INFO:aiogram.dispatcher:Start polling
INFO:aiogram.dispatcher:Run polling for bot @NordEdokBot id=6797344572 - 'NordEdokBot'
INFO:aiogram.event:Update id=688885334 is handled. Duration 312 ms by bot id=6797344572
INFO:aiogram.event:Update id=688885335 is handled. Duration 343 ms by bot id=6797344572
INFO:aiogram.event:Update id=688885336 is handled. Duration 172 ms by bot id=6797344572
INFO:aiogram.event:Update id=688885337 is handled. Duration 389 ms by bot id=6797344572
INFO:googleapiclient.discovery_cache:file_cache is only supported with oauth2client<4.0.0
[{'spreadsheetId': '17DQRfmDI8Ou-uISBxEj0_fUlF2uv2i_LhJ854_-hVvY', 'tableRange': "'Главная'!B4:J17", 'updates': {'spreadsheetId': '17DQRfmDI8Ou-uISBxEj0_fUlF2uv2i_LhJ854_-hVvY', 'updatedRange': "'Главная'!B18:J18", 'updatedRows': 1, 'updatedColumns': 9, 'updatedCells': 9}}]
INFO:aiogram.event:Update id=688885338 is handled. Duration 1500 ms by bot id=6797344572
INFO:aiogram.dispatcher:Polling stopped
INFO:aiogram.dispatcher:Polling stopped for bot @NordEdokBot id=6797344572 - 'NordEdokBot'
Traceback (most recent call last):
  File "C:\Users\user\AppData\Local\Programs\Python\Python311\Lib\asyncio\runners.py", line 118, in run
    return self._loop.run_until_complete(task)
           ^^^^^^^^^^^^^^^^^^^^^^^^^^^^^^^^^^^
  File "C:\Users\user\AppData\Local\Programs\Python\Python311\Lib\asyncio\base_events.py", line 653, in run_until_complete
    return future.result()
           ^^^^^^^^^^^^^^^
  File "D:\Dev\!PROJECTS\edok_bot\main.py", line 15, in main
    await dp.start_polling(bot)
  File "D:\Dev\!PROJECTS\edok_bot\venv\Lib\site-packages\aiogram\dispatcher\dispatcher.py", line 543, in start_polling
    done, pending = await asyncio.wait(tasks, return_when=asyncio.FIRST_COMPLETED)
                    ^^^^^^^^^^^^^^^^^^^^^^^^^^^^^^^^^^^^^^^^^^^^^^^^^^^^^^^^^^^^^^
  File "C:\Users\user\AppData\Local\Programs\Python\Python311\Lib\asyncio\tasks.py", line 428, in wait
    return await _wait(fs, timeout, return_when, loop)
           ^^^^^^^^^^^^^^^^^^^^^^^^^^^^^^^^^^^^^^^^^^^
  File "C:\Users\user\AppData\Local\Programs\Python\Python311\Lib\asyncio\tasks.py", line 535, in _wait
    await waiter
asyncio.exceptions.CancelledError

During handling of the above exception, another exception occurred:

Traceback (most recent call last):
  File "D:\Dev\!PROJECTS\edok_bot\main.py", line 22, in <module>
    asyncio.run(main())
  File "C:\Users\user\AppData\Local\Programs\Python\Python311\Lib\asyncio\runners.py", line 190, in run
    return runner.run(main)
           ^^^^^^^^^^^^^^^^
  File "C:\Users\user\AppData\Local\Programs\Python\Python311\Lib\asyncio\runners.py", line 123, in run
    raise KeyboardInterrupt()
KeyboardInterrupt
INFO:aiogram.dispatcher:Start polling
INFO:aiogram.dispatcher:Run polling for bot @NordEdokBot id=6797344572 - 'NordEdokBot'
INFO:aiogram.dispatcher:Polling stopped
INFO:aiogram.dispatcher:Polling stopped for bot @NordEdokBot id=6797344572 - 'NordEdokBot'
Traceback (most recent call last):
  File "C:\Users\user\AppData\Local\Programs\Python\Python311\Lib\asyncio\runners.py", line 118, in run
    return self._loop.run_until_complete(task)
           ^^^^^^^^^^^^^^^^^^^^^^^^^^^^^^^^^^^
  File "C:\Users\user\AppData\Local\Programs\Python\Python311\Lib\asyncio\base_events.py", line 653, in run_until_complete
    return future.result()
           ^^^^^^^^^^^^^^^
  File "D:\Dev\!PROJECTS\edok_bot\main.py", line 15, in main
    await dp.start_polling(bot)
  File "D:\Dev\!PROJECTS\edok_bot\venv\Lib\site-packages\aiogram\dispatcher\dispatcher.py", line 543, in start_polling
    done, pending = await asyncio.wait(tasks, return_when=asyncio.FIRST_COMPLETED)
                    ^^^^^^^^^^^^^^^^^^^^^^^^^^^^^^^^^^^^^^^^^^^^^^^^^^^^^^^^^^^^^^
  File "C:\Users\user\AppData\Local\Programs\Python\Python311\Lib\asyncio\tasks.py", line 428, in wait
    return await _wait(fs, timeout, return_when, loop)
           ^^^^^^^^^^^^^^^^^^^^^^^^^^^^^^^^^^^^^^^^^^^
  File "C:\Users\user\AppData\Local\Programs\Python\Python311\Lib\asyncio\tasks.py", line 535, in _wait
    await waiter
asyncio.exceptions.CancelledError

During handling of the above exception, another exception occurred:

Traceback (most recent call last):
  File "D:\Dev\!PROJECTS\edok_bot\main.py", line 22, in <module>
    asyncio.run(main())
  File "C:\Users\user\AppData\Local\Programs\Python\Python311\Lib\asyncio\runners.py", line 190, in run
    return runner.run(main)
           ^^^^^^^^^^^^^^^^
  File "C:\Users\user\AppData\Local\Programs\Python\Python311\Lib\asyncio\runners.py", line 123, in run
    raise KeyboardInterrupt()
KeyboardInterrupt
